<?xml version="1.0" encoding="UTF-8"?>
<mujoco model="sundog_allthread">
    <compiler angle="radian" coordinate="local"/>
    <option gravity="0 0 -9.81" integrator="RK4" timestep="0.01"/>

    <default>
        <geom rgba="0.6 0.6 0.6 1" friction="1 0.5 0.001"/>
    </default>

    <worldbody>
        <!-- Ground -->
        <geom name="floor" type="plane" pos="0 0 0" size="5 5 0.1" rgba="0.8 0.9 0.8 1"/>

        <!-- Ceiling with target -->
        <geom name="ceiling" type="plane" pos="0 0 2.5" size="5 5 0.1" rgba="0.8 0.8 1 1" euler="0 0 3.1416"/>
        <site name="laser_dot" pos="0 0 2.5" size="0.02" rgba="1 0 0 1"/>

        <!-- Telescoping pole representing a conduit or rod -->
        <body name="base" pos="0 0 0.1">
            <geom type="cylinder" size="0.03 0.1"/>
            <joint name="base_rotate" type="hinge" axis="0 0 1"/>
            <body name="segment1" pos="0 0 0.2">
                <geom type="capsule" size="0.015 0.75" fromto="0 0 0 0 0 1"/>
                <joint name="pitch1" type="hinge" axis="1 0 0"/>
                <body name="segment2" pos="0 0 1.5">
                    <geom type="capsule" size="0.01 0.75" fromto="0 0 0 0 0 1"/>
                    <joint name="pitch2" type="hinge" axis="1 0 0"/>
                    <site name="tip" pos="0 0 1.5" size="0.01" rgba="0 1 0 1"/>
                </body>
            </body>
        </body>
    </worldbody>

    <actuator>
        <motor joint="base_rotate" ctrlrange="-1 1"/>
        <motor joint="pitch1" ctrlrange="-1 1"/>
        <motor joint="pitch2" ctrlrange="-1 1"/>
    </actuator>
</mujoco>
